Traceback (most recent call last):
  File "c:\hostedtoolcache\windows\python\3.8.10\x64\lib\site-packages\jupyter_cache\executors\utils.py", line 51, in single_nb_execution
    executenb(
  File "c:\hostedtoolcache\windows\python\3.8.10\x64\lib\site-packages\nbclient\client.py", line 1204, in execute
    return NotebookClient(nb=nb, resources=resources, km=km, **kwargs).execute()
  File "c:\hostedtoolcache\windows\python\3.8.10\x64\lib\site-packages\nbclient\util.py", line 84, in wrapped
    return just_run(coro(*args, **kwargs))
  File "c:\hostedtoolcache\windows\python\3.8.10\x64\lib\site-packages\nbclient\util.py", line 62, in just_run
    return loop.run_until_complete(coro)
  File "c:\hostedtoolcache\windows\python\3.8.10\x64\lib\asyncio\base_events.py", line 616, in run_until_complete
    return future.result()
  File "c:\hostedtoolcache\windows\python\3.8.10\x64\lib\site-packages\nbclient\client.py", line 663, in async_execute
    await self.async_execute_cell(
  File "c:\hostedtoolcache\windows\python\3.8.10\x64\lib\site-packages\nbclient\client.py", line 965, in async_execute_cell
    await self._check_raise_for_error(cell, cell_index, exec_reply)
  File "c:\hostedtoolcache\windows\python\3.8.10\x64\lib\site-packages\nbclient\client.py", line 862, in _check_raise_for_error
    raise CellExecutionError.from_cell_and_msg(cell, exec_reply_content)
nbclient.exceptions.CellExecutionError: An error occurred while executing the following cell:
------------------
# install.packages("librarian", quiet = T)
librarian::shelf(tidyverse, lmtest, sandwich, broom, hdm, quiet = T)
## loading the data
Penn <- as_tibble(read.table("https://github.com/d2cml-ai/14.388_r/raw/main/Data/penn_jae.dat", header=T ))
n <- dim(Penn)[1]
p_1 <- dim(Penn)[2]
Penn <- filter(Penn, tg == 4 | tg == 0)# subset(Penn, tg==4 | tg==0)
attach(Penn)
------------------

Error in file(file, "rt"): cannot open the connection to 'https://github.com/d2cml-ai/14.388_r/raw/main/Data/penn_jae.dat'
Traceback:

1. as_tibble(read.table("https://github.com/d2cml-ai/14.388_r/raw/main/Data/penn_jae.dat", 
 .     header = T))
2. read.table("https://github.com/d2cml-ai/14.388_r/raw/main/Data/penn_jae.dat", 
 .     header = T)   # at line 60 of file C:/Users/runneradmin/AppData/Local/Temp/Rtmp0WK7Ml/R.INSTALL1b0c6592180c/tibble/R/as_tibble.R
3. file(file, "rt")
ERROR: Error in file(file, "rt"): cannot open the connection to 'https://github.com/d2cml-ai/14.388_r/raw/main/Data/penn_jae.dat'


